Workbook
Name TEST0: #REF!
Name TEST0: #REF!
Name TEST1014: #REF!
Name TESTHKEY: #REF!
Name TESTHKEY: #REF!
Name TESTKEYS: #REF!
Name TESTKEYS: #REF!
Name TESTVKEY: #REF!
Name TESTVKEY: #REF!
Name Today: TableToday[]
Name Yesterday: #REF!

Sheet Main
A1: Crop | B1: Material Description | C1: Prod. Order | D1: Output Qty | E1: UOM | F1: Scheduled Finish Date (SAP) | G1: Notes: | H1: Priority | I1: PO Status | J1: WorkCenter | K1: Pack Line | L1: Department | M1: Hours | N1: Capacity
A2: =TRIM(LEFT(B2,4)) -> SWCO | B2: SWCO GSS2259P CRS CLX ZZZ BK KG | C2: 300102044 | D2: 1035 | E2: KG | F2: 46209 | G2: SEEDS NEEDS REWORKED FOR AP+ 2 X. THIS | I2: ="NEW" -> NEW | J2: =IFERROR(VLOOKUP(TableToday[[#This Row],[Prod. Order]],Components!A:B,2,FALSE), "0") -> LSVGRVTY | K2: =IFERROR(VLOOKUP(TableToday[[#This Row],[WorkCenter]],'Resource Info'!A:B,2,FALSE), "0") -> LSV Gravity | L2: =IFERROR(VLOOKUP(TableToday[[#This Row],[Pack Line]],'Resource Info'!B:C,2,FALSE),"0") -> LSV Conditioning | M2: =IF(OR(TableToday[[#This Row],[Department]]="SSV TREATPACK", TableToday[[#This Row],[Department]]="LSV TREATPACK"), VLOOKUP(TableToday[[#This Row],[Pack Line]],'Packaging Rates'!$A$2:$C$9,3,FALSE)+ (TableToday[[#This Row],[Output Qty]]/(VLOOKUP(TableToday[[#This Row],[Pack Line]],'Packaging Rates'!$A$2:$C$9,2,FALSE))),"") | N2: =IF(OR(TableToday[[#This Row],[Department]]="SSV TREATPACK", TableToday[[#This Row],[Department]]="LSV TREATPACK"),8,"")
A3: =TRIM(LEFT(B3,4)) -> SWCO | B3: SWCO OVERLAND CRS CLX ZZZ BK KG | C3: 1002307551 | D3: 6400 | E3: KG | F3: 46324 | G3: SWCO RAX-CLX SUP INT Ln1 | H3: 2 | I3: ="NEW" -> NEW | J3: =IFERROR(VLOOKUP(TableToday[[#This Row],[Prod. Order]],Components!A:B,2,FALSE), "0") -> LSVLN2 | K3: =IFERROR(VLOOKUP(TableToday[[#This Row],[WorkCenter]],'Resource Info'!A:B,2,FALSE), "0") -> LSV Line 2 | L3: =IFERROR(VLOOKUP(TableToday[[#This Row],[Pack Line]],'Resource Info'!B:C,2,FALSE),"0") -> LSV Conditioning | M3: =IF(OR(TableToday[[#This Row],[Department]]="SSV TREATPACK", TableToday[[#This Row],[Department]]="LSV TREATPACK"), VLOOKUP(TableToday[[#This Row],[Pack Line]],'Packaging Rates'!$A$2:$C$9,3,FALSE)+ (TableToday[[#This Row],[Output Qty]]/(VLOOKUP(TableToday[[#This Row],[Pack Line]],'Packaging Rates'!$A$2:$C$9,2,FALSE))),"") | N3: =IF(OR(TableToday[[#This Row],[Department]]="SSV TREATPACK", TableToday[[#This Row],[Department]]="LSV TREATPACK"),8,"")
A4: =TRIM(LEFT(B4,4)) -> SWBS | B4: SWBS R00565H S CRS CLD ZZZ BK KG | C4: 1002302915 | D4: 360.5 | E4: KG | F4: 46341 | G4: SWBS RAW-CLD INT Ln1 | H4: 5 | I4: ="NEW" -> NEW | J4: =IFERROR(VLOOKUP(TableToday[[#This Row],[Prod. Order]],Components!A:B,2,FALSE), "0") -> LSVLN1 | K4: =IFERROR(VLOOKUP(TableToday[[#This Row],[WorkCenter]],'Resource Info'!A:B,2,FALSE), "0") -> LSV Line 1 | L4: =IFERROR(VLOOKUP(TableToday[[#This Row],[Pack Line]],'Resource Info'!B:C,2,FALSE),"0") -> LSV Conditioning | M4: =IF(OR(TableToday[[#This Row],[Department]]="SSV TREATPACK", TableToday[[#This Row],[Department]]="LSV TREATPACK"), VLOOKUP(TableToday[[#This Row],[Pack Line]],'Packaging Rates'!$A$2:$C$9,3,FALSE)+ (TableToday[[#This Row],[Output Qty]]/(VLOOKUP(TableToday[[#This Row],[Pack Line]],'Packaging Rates'!$A$2:$C$9,2,FALSE))),"") | N4: =IF(OR(TableToday[[#This Row],[Department]]="SSV TREATPACK", TableToday[[#This Row],[Department]]="LSV TREATPACK"),8,"")
A5: =TRIM(LEFT(B5,4)) -> SWBS | B5: SWBS R00565H S CRS CLD ZZZ BK KG | C5: 1002302916 | D5: 697.5 | E5: KG | F5: 46341 | G5: SWBS RAW-CLD INT Ln1 | H5: 5 | I5: ="NEW" -> NEW | J5: =IFERROR(VLOOKUP(TableToday[[#This Row],[Prod. Order]],Components!A:B,2,FALSE), "0") -> LSVLN1 | K5: =IFERROR(VLOOKUP(TableToday[[#This Row],[WorkCenter]],'Resource Info'!A:B,2,FALSE), "0") -> LSV Line 1 | L5: =IFERROR(VLOOKUP(TableToday[[#This Row],[Pack Line]],'Resource Info'!B:C,2,FALSE),"0") -> LSV Conditioning | M5: =IF(OR(TableToday[[#This Row],[Department]]="SSV TREATPACK", TableToday[[#This Row],[Department]]="LSV TREATPACK"), VLOOKUP(TableToday[[#This Row],[Pack Line]],'Packaging Rates'!$A$2:$C$9,3,FALSE)+ (TableToday[[#This Row],[Output Qty]]/(VLOOKUP(TableToday[[#This Row],[Pack Line]],'Packaging Rates'!$A$2:$C$9,2,FALSE))),"") | N5: =IF(OR(TableToday[[#This Row],[Department]]="SSV TREATPACK", TableToday[[#This Row],[Department]]="LSV TREATPACK"),8,"")
A6: =TRIM(LEFT(B6,4)) -> SWCO | B6: SWCO GSS3951 CRS CLX ZZZ BK KG | C6: 1002174855 | D6: 48400 | E6: KG | F6: 46021 | G6: SWCO RAX-CLX SUP INT Ln1 | H6: 1 | I6: ="NEW" -> NEW | J6: =IFERROR(VLOOKUP(TableToday[[#This Row],[Prod. Order]],Components!A:B,2,FALSE), "0") -> LSVLN1 | K6: =IFERROR(VLOOKUP(TableToday[[#This Row],[WorkCenter]],'Resource Info'!A:B,2,FALSE), "0") -> LSV Line 1 | L6: =IFERROR(VLOOKUP(TableToday[[#This Row],[Pack Line]],'Resource Info'!B:C,2,FALSE),"0") -> LSV Conditioning | M6: =IF(OR(TableToday[[#This Row],[Department]]="SSV TREATPACK", TableToday[[#This Row],[Department]]="LSV TREATPACK"), VLOOKUP(TableToday[[#This Row],[Pack Line]],'Packaging Rates'!$A$2:$C$9,3,FALSE)+ (TableToday[[#This Row],[Output Qty]]/(VLOOKUP(TableToday[[#This Row],[Pack Line]],'Packaging Rates'!$A$2:$C$9,2,FALSE))),"") | N6: =IF(OR(TableToday[[#This Row],[Department]]="SSV TREATPACK", TableToday[[#This Row],[Department]]="LSV TREATPACK"),8,"")
A7: =TRIM(LEFT(B7,4)) -> SWCO | B7: SWCO GSS3951 CRS CLX ZZZ BK KG | C7: 2400008125 | D7: 3994 | E7: KG | F7: 46265 | G7: REWORKING TO REMOVE SMALL SEED. SCREEN | I7: ="NEW" -> NEW | J7: =IFERROR(VLOOKUP(TableToday[[#This Row],[Prod. Order]],Components!A:B,2,FALSE), "0") -> LSVGRVTY | K7: =IFERROR(VLOOKUP(TableToday[[#This Row],[WorkCenter]],'Resource Info'!A:B,2,FALSE), "0") -> LSV Gravity | L7: =IFERROR(VLOOKUP(TableToday[[#This Row],[Pack Line]],'Resource Info'!B:C,2,FALSE),"0") -> LSV Conditioning | M7: =IF(OR(TableToday[[#This Row],[Department]]="SSV TREATPACK", TableToday[[#This Row],[Department]]="LSV TREATPACK"), VLOOKUP(TableToday[[#This Row],[Pack Line]],'Packaging Rates'!$A$2:$C$9,3,FALSE)+ (TableToday[[#This Row],[Output Qty]]/(VLOOKUP(TableToday[[#This Row],[Pack Line]],'Packaging Rates'!$A$2:$C$9,2,FALSE))),"") | N7: =IF(OR(TableToday[[#This Row],[Department]]="SSV TREATPACK", TableToday[[#This Row],[Department]]="LSV TREATPACK"),8,"")
A8: =TRIM(LEFT(B8,4)) -> SWCO | B8: SWCO GH6055 CRN CLX ZZZ BK KG | C8: 1002181889 | D8: 42000 | E8: KG | F8: 46020 | G8: SWCO RAX-CLX STD INT Ln1 | H8: 7 | I8: ="NEW" -> NEW | J8: =IFERROR(VLOOKUP(TableToday[[#This Row],[Prod. Order]],Components!A:B,2,FALSE), "0") -> LSVLN1 | K8: =IFERROR(VLOOKUP(TableToday[[#This Row],[WorkCenter]],'Resource Info'!A:B,2,FALSE), "0") -> LSV Line 1 | L8: =IFERROR(VLOOKUP(TableToday[[#This Row],[Pack Line]],'Resource Info'!B:C,2,FALSE),"0") -> LSV Conditioning | M8: =IF(OR(TableToday[[#This Row],[Department]]="SSV TREATPACK", TableToday[[#This Row],[Department]]="LSV TREATPACK"), VLOOKUP(TableToday[[#This Row],[Pack Line]],'Packaging Rates'!$A$2:$C$9,3,FALSE)+ (TableToday[[#This Row],[Output Qty]]/(VLOOKUP(TableToday[[#This Row],[Pack Line]],'Packaging Rates'!$A$2:$C$9,2,FALSE))),"") | N8: =IF(OR(TableToday[[#This Row],[Department]]="SSV TREATPACK", TableToday[[#This Row],[Department]]="LSV TREATPACK"),8,"")
A9: =TRIM(LEFT(B9,4)) -> SWCO | B9: SWCO GH6055 CRN CLX ZZZ BK KG | C9: 300102084 | D9: 564.5 | E9: KG | F9: 46210 | G9: NEEDS REWORKED FOR FAILED TARE X 2. THI | I9: ="NEW" -> NEW | J9: =IFERROR(VLOOKUP(TableToday[[#This Row],[Prod. Order]],Components!A:B,2,FALSE), "0") -> LSVGRVTY | K9: =IFERROR(VLOOKUP(TableToday[[#This Row],[WorkCenter]],'Resource Info'!A:B,2,FALSE), "0") -> LSV Gravity | L9: =IFERROR(VLOOKUP(TableToday[[#This Row],[Pack Line]],'Resource Info'!B:C,2,FALSE),"0") -> LSV Conditioning | M9: =IF(OR(TableToday[[#This Row],[Department]]="SSV TREATPACK", TableToday[[#This Row],[Department]]="LSV TREATPACK"), VLOOKUP(TableToday[[#This Row],[Pack Line]],'Packaging Rates'!$A$2:$C$9,3,FALSE)+ (TableToday[[#This Row],[Output Qty]]/(VLOOKUP(TableToday[[#This Row],[Pack Line]],'Packaging Rates'!$A$2:$C$9,2,FALSE))),"") | N9: =IF(OR(TableToday[[#This Row],[Department]]="SSV TREATPACK", TableToday[[#This Row],[Department]]="LSV TREATPACK"),8,"")
A10: =TRIM(LEFT(B10,4)) -> SWBS | B10: SWBS R29153 T CRS CLX ZZZ BK KG | C10: 1002270166 | D10: 1939 | E10: KG | F10: 46164 | G10: SWBS RAX-CLX INT L2B | I10: ="NEW" -> NEW | J10: =IFERROR(VLOOKUP(TableToday[[#This Row],[Prod. Order]],Components!A:B,2,FALSE), "0") -> LSVLN2 | K10: =IFERROR(VLOOKUP(TableToday[[#This Row],[WorkCenter]],'Resource Info'!A:B,2,FALSE), "0") -> LSV Line 2 | L10: =IFERROR(VLOOKUP(TableToday[[#This Row],[Pack Line]],'Resource Info'!B:C,2,FALSE),"0") -> LSV Conditioning | M10: =IF(OR(TableToday[[#This Row],[Department]]="SSV TREATPACK", TableToday[[#This Row],[Department]]="LSV TREATPACK"), VLOOKUP(TableToday[[#This Row],[Pack Line]],'Packaging Rates'!$A$2:$C$9,3,FALSE)+ (TableToday[[#This Row],[Output Qty]]/(VLOOKUP(TableToday[[#This Row],[Pack Line]],'Packaging Rates'!$A$2:$C$9,2,FALSE))),"") | N10: =IF(OR(TableToday[[#This Row],[Department]]="SSV TREATPACK", TableToday[[#This Row],[Department]]="LSV TREATPACK"),8,"")
A11: =TRIM(LEFT(B11,4)) -> SWCO | B11: SWCO OVERLAND CRS RDY ZZZ BK KG | C11: 1002307550 | D11: 3300 | E11: KG | F11: 46324 | G11: SWCO RAW RDY SUP INT Ln1 | H11: 4 | I11: ="NEW" -> NEW | J11: =IFERROR(VLOOKUP(TableToday[[#This Row],[Prod. Order]],Components!A:B,2,FALSE), "0") -> LSVLN2 | K11: =IFERROR(VLOOKUP(TableToday[[#This Row],[WorkCenter]],'Resource Info'!A:B,2,FALSE), "0") -> LSV Line 2 | L11: =IFERROR(VLOOKUP(TableToday[[#This Row],[Pack Line]],'Resource Info'!B:C,2,FALSE),"0") -> LSV Conditioning | M11: =IF(OR(TableToday[[#This Row],[Department]]="SSV TREATPACK", TableToday[[#This Row],[Department]]="LSV TREATPACK"), VLOOKUP(TableToday[[#This Row],[Pack Line]],'Packaging Rates'!$A$2:$C$9,3,FALSE)+ (TableToday[[#This Row],[Output Qty]]/(VLOOKUP(TableToday[[#This Row],[Pack Line]],'Packaging Rates'!$A$2:$C$9,2,FALSE))),"") | N11: =IF(OR(TableToday[[#This Row],[Department]]="SSV TREATPACK", TableToday[[#This Row],[Department]]="LSV TREATPACK"),8,"")
A12: =TRIM(LEFT(B12,4)) -> MEBS | B12: MEBS 1M064 RDY ZZZ BK KS | C12: 1002306429 | D12: 10.66 | E12: KG | F12: 46296 | G12: MEBS RAW RDY INT | I12: ="NEW" -> NEW | J12: =IFERROR(VLOOKUP(TableToday[[#This Row],[Prod. Order]],Components!A:B,2,FALSE), "0") -> SSVLN5 | K12: =IFERROR(VLOOKUP(TableToday[[#This Row],[WorkCenter]],'Resource Info'!A:B,2,FALSE), "0") -> SSV Line 5 | L12: =IFERROR(VLOOKUP(TableToday[[#This Row],[Pack Line]],'Resource Info'!B:C,2,FALSE),"0") -> SSV Conditioning | M12: =IF(OR(TableToday[[#This Row],[Department]]="SSV TREATPACK", TableToday[[#This Row],[Department]]="LSV TREATPACK"), VLOOKUP(TableToday[[#This Row],[Pack Line]],'Packaging Rates'!$A$2:$C$9,3,FALSE)+ (TableToday[[#This Row],[Output Qty]]/(VLOOKUP(TableToday[[#This Row],[Pack Line]],'Packaging Rates'!$A$2:$C$9,2,FALSE))),"") | N12: =IF(OR(TableToday[[#This Row],[Department]]="SSV TREATPACK", TableToday[[#This Row],[Department]]="LSV TREATPACK"),8,"")
A13: =TRIM(LEFT(B13,4)) -> MECO | B13: MECO OVATION RDY ZZZ BK KS | C13: 1002301022 | D13: 96 | E13: KG | F13: 46273 | G13: MECO RAW RDY Ln1 INT | I13: ="NEW" -> NEW | J13: =IFERROR(VLOOKUP(TableToday[[#This Row],[Prod. Order]],Components!A:B,2,FALSE), "0") -> SSVLN6 | K13: =IFERROR(VLOOKUP(TableToday[[#This Row],[WorkCenter]],'Resource Info'!A:B,2,FALSE), "0") -> SSV Line 6 | L13: =IFERROR(VLOOKUP(TableToday[[#This Row],[Pack Line]],'Resource Info'!B:C,2,FALSE),"0") -> SSV Conditioning | M13: =IF(OR(TableToday[[#This Row],[Department]]="SSV TREATPACK", TableToday[[#This Row],[Department]]="LSV TREATPACK"), VLOOKUP(TableToday[[#This Row],[Pack Line]],'Packaging Rates'!$A$2:$C$9,3,FALSE)+ (TableToday[[#This Row],[Output Qty]]/(VLOOKUP(TableToday[[#This Row],[Pack Line]],'Packaging Rates'!$A$2:$C$9,2,FALSE))),"") | N13: =IF(OR(TableToday[[#This Row],[Department]]="SSV TREATPACK", TableToday[[#This Row],[Department]]="LSV TREATPACK"),8,"")
A14: =TRIM(LEFT(B14,4)) -> MECO | B14: MECO OVATION RDY ZZZ BK KS | C14: 1002301023 | D14: 89 | E14: KG | F14: 46274 | G14: MECO RAW RDY Ln1 INT | I14: ="NEW" -> NEW | J14: =IFERROR(VLOOKUP(TableToday[[#This Row],[Prod. Order]],Components!A:B,2,FALSE), "0") -> SSVLN6 | K14: =IFERROR(VLOOKUP(TableToday[[#This Row],[WorkCenter]],'Resource Info'!A:B,2,FALSE), "0") -> SSV Line 6 | L14: =IFERROR(VLOOKUP(TableToday[[#This Row],[Pack Line]],'Resource Info'!B:C,2,FALSE),"0") -> SSV Conditioning | M14: =IF(OR(TableToday[[#This Row],[Department]]="SSV TREATPACK", TableToday[[#This Row],[Department]]="LSV TREATPACK"), VLOOKUP(TableToday[[#This Row],[Pack Line]],'Packaging Rates'!$A$2:$C$9,3,FALSE)+ (TableToday[[#This Row],[Output Qty]]/(VLOOKUP(TableToday[[#This Row],[Pack Line]],'Packaging Rates'!$A$2:$C$9,2,FALSE))),"") | N14: =IF(OR(TableToday[[#This Row],[Department]]="SSV TREATPACK", TableToday[[#This Row],[Department]]="LSV TREATPACK"),8,"")
A15: =TRIM(LEFT(B15,4)) -> MECO | B15: MECO OVATION RDY ZZZ BK KS | C15: 1002302359 | D15: 85 | E15: KG | F15: 46289 | G15: MECO RAW RDY Ln1 INT | I15: ="NEW" -> NEW | J15: =IFERROR(VLOOKUP(TableToday[[#This Row],[Prod. Order]],Components!A:B,2,FALSE), "0") -> SSVLN6 | K15: =IFERROR(VLOOKUP(TableToday[[#This Row],[WorkCenter]],'Resource Info'!A:B,2,FALSE), "0") -> SSV Line 6 | L15: =IFERROR(VLOOKUP(TableToday[[#This Row],[Pack Line]],'Resource Info'!B:C,2,FALSE),"0") -> SSV Conditioning | M15: =IF(OR(TableToday[[#This Row],[Department]]="SSV TREATPACK", TableToday[[#This Row],[Department]]="LSV TREATPACK"), VLOOKUP(TableToday[[#This Row],[Pack Line]],'Packaging Rates'!$A$2:$C$9,3,FALSE)+ (TableToday[[#This Row],[Output Qty]]/(VLOOKUP(TableToday[[#This Row],[Pack Line]],'Packaging Rates'!$A$2:$C$9,2,FALSE))),"") | N15: =IF(OR(TableToday[[#This Row],[Department]]="SSV TREATPACK", TableToday[[#This Row],[Department]]="LSV TREATPACK"),8,"")
A16: =TRIM(LEFT(B16,4)) -> MECO | B16: MECO OVATION RDY ZZZ BK KS | C16: 1002302361 | D16: 80.464 | E16: KG | F16: 46289 | G16: MECO RAW RDY Ln1 INT | I16: ="NEW" -> NEW | J16: =IFERROR(VLOOKUP(TableToday[[#This Row],[Prod. Order]],Components!A:B,2,FALSE), "0") -> SSVLN6 | K16: =IFERROR(VLOOKUP(TableToday[[#This Row],[WorkCenter]],'Resource Info'!A:B,2,FALSE), "0") -> SSV Line 6 | L16: =IFERROR(VLOOKUP(TableToday[[#This Row],[Pack Line]],'Resource Info'!B:C,2,FALSE),"0") -> SSV Conditioning | M16: =IF(OR(TableToday[[#This Row],[Department]]="SSV TREATPACK", TableToday[[#This Row],[Department]]="LSV TREATPACK"), VLOOKUP(TableToday[[#This Row],[Pack Line]],'Packaging Rates'!$A$2:$C$9,3,FALSE)+ (TableToday[[#This Row],[Output Qty]]/(VLOOKUP(TableToday[[#This Row],[Pack Line]],'Packaging Rates'!$A$2:$C$9,2,FALSE))),"") | N16: =IF(OR(TableToday[[#This Row],[Department]]="SSV TREATPACK", TableToday[[#This Row],[Department]]="LSV TREATPACK"),8,"")
A17: =TRIM(LEFT(B17,4)) -> MECO | B17: MECO OVATION RDY ZZZ BK KS | C17: 1002302362 | D17: 169 | E17: KG | F17: 46289 | G17: MECO RAW RDY Ln1 INT | I17: ="NEW" -> NEW | J17: =IFERROR(VLOOKUP(TableToday[[#This Row],[Prod. Order]],Components!A:B,2,FALSE), "0") -> SSVLN6 | K17: =IFERROR(VLOOKUP(TableToday[[#This Row],[WorkCenter]],'Resource Info'!A:B,2,FALSE), "0") -> SSV Line 6 | L17: =IFERROR(VLOOKUP(TableToday[[#This Row],[Pack Line]],'Resource Info'!B:C,2,FALSE),"0") -> SSV Conditioning | M17: =IF(OR(TableToday[[#This Row],[Department]]="SSV TREATPACK", TableToday[[#This Row],[Department]]="LSV TREATPACK"), VLOOKUP(TableToday[[#This Row],[Pack Line]],'Packaging Rates'!$A$2:$C$9,3,FALSE)+ (TableToday[[#This Row],[Output Qty]]/(VLOOKUP(TableToday[[#This Row],[Pack Line]],'Packaging Rates'!$A$2:$C$9,2,FALSE))),"") | N17: =IF(OR(TableToday[[#This Row],[Department]]="SSV TREATPACK", TableToday[[#This Row],[Department]]="LSV TREATPACK"),8,"")
A18: =TRIM(LEFT(B18,4)) -> SQCO | B18: SQCO NOCHE RDY ZZZ BK KS | C18: 1002307492 | D18: 21.82 | E18: KG | F18: 46300 | G18: SQCO RAW RDY Ln1 INT | I18: ="NEW" -> NEW | J18: =IFERROR(VLOOKUP(TableToday[[#This Row],[Prod. Order]],Components!A:B,2,FALSE), "0") -> SSVLN5 | K18: =IFERROR(VLOOKUP(TableToday[[#This Row],[WorkCenter]],'Resource Info'!A:B,2,FALSE), "0") -> SSV Line 5 | L18: =IFERROR(VLOOKUP(TableToday[[#This Row],[Pack Line]],'Resource Info'!B:C,2,FALSE),"0") -> SSV Conditioning | M18: =IF(OR(TableToday[[#This Row],[Department]]="SSV TREATPACK", TableToday[[#This Row],[Department]]="LSV TREATPACK"), VLOOKUP(TableToday[[#This Row],[Pack Line]],'Packaging Rates'!$A$2:$C$9,3,FALSE)+ (TableToday[[#This Row],[Output Qty]]/(VLOOKUP(TableToday[[#This Row],[Pack Line]],'Packaging Rates'!$A$2:$C$9,2,FALSE))),"") | N18: =IF(OR(TableToday[[#This Row],[Department]]="SSV TREATPACK", TableToday[[#This Row],[Department]]="LSV TREATPACK"),8,"")
A19: =TRIM(LEFT(B19,4)) -> BECO | B19: BECO ORGANDI RDY ZZZ BK KG | C19: 1002303195 | D19: 10820 | E19: KG | F19: 46384 | G19: BECO RAW RDY Ln2 INT KENYA | H19: 8 | I19: ="NEW" -> NEW | J19: =IFERROR(VLOOKUP(TableToday[[#This Row],[Prod. Order]],Components!A:B,2,FALSE), "0") -> LSVLN2 | K19: =IFERROR(VLOOKUP(TableToday[[#This Row],[WorkCenter]],'Resource Info'!A:B,2,FALSE), "0") -> LSV Line 2 | L19: =IFERROR(VLOOKUP(TableToday[[#This Row],[Pack Line]],'Resource Info'!B:C,2,FALSE),"0") -> LSV Conditioning | M19: =IF(OR(TableToday[[#This Row],[Department]]="SSV TREATPACK", TableToday[[#This Row],[Department]]="LSV TREATPACK"), VLOOKUP(TableToday[[#This Row],[Pack Line]],'Packaging Rates'!$A$2:$C$9,3,FALSE)+ (TableToday[[#This Row],[Output Qty]]/(VLOOKUP(TableToday[[#This Row],[Pack Line]],'Packaging Rates'!$A$2:$C$9,2,FALSE))),"") | N19: =IF(OR(TableToday[[#This Row],[Department]]="SSV TREATPACK", TableToday[[#This Row],[Department]]="LSV TREATPACK"),8,"")
A20: =TRIM(LEFT(B20,4)) -> PECO | B20: PECO SP704-3-8 SNP RDY ZZZ BK KG | C20: 1002266351 | D20: 23170 | E20: KG | F20: 46265 | G20: PECO PEA RAW RDY Ln2 INT | H20: 7 | I20: ="NEW" -> NEW | J20: =IFERROR(VLOOKUP(TableToday[[#This Row],[Prod. Order]],Components!A:B,2,FALSE), "0") -> LSVLN1 | K20: =IFERROR(VLOOKUP(TableToday[[#This Row],[WorkCenter]],'Resource Info'!A:B,2,FALSE), "0") -> LSV Line 1 | L20: =IFERROR(VLOOKUP(TableToday[[#This Row],[Pack Line]],'Resource Info'!B:C,2,FALSE),"0") -> LSV Conditioning | M20: =IF(OR(TableToday[[#This Row],[Department]]="SSV TREATPACK", TableToday[[#This Row],[Department]]="LSV TREATPACK"), VLOOKUP(TableToday[[#This Row],[Pack Line]],'Packaging Rates'!$A$2:$C$9,3,FALSE)+ (TableToday[[#This Row],[Output Qty]]/(VLOOKUP(TableToday[[#This Row],[Pack Line]],'Packaging Rates'!$A$2:$C$9,2,FALSE))),"") | N20: =IF(OR(TableToday[[#This Row],[Department]]="SSV TREATPACK", TableToday[[#This Row],[Department]]="LSV TREATPACK"),8,"")
A21: =TRIM(LEFT(B21,4)) -> PECO | B21: PECO SP704-3-8 SNP RDY ZZZ BK KG | C21: 1002266886 | D21: 35230 | E21: KG | F21: 46265 | G21: PECO PEA RAW RDY Ln2 INT | H21: 7 | I21: ="NEW" -> NEW | J21: =IFERROR(VLOOKUP(TableToday[[#This Row],[Prod. Order]],Components!A:B,2,FALSE), "0") -> LSVLN1 | K21: =IFERROR(VLOOKUP(TableToday[[#This Row],[WorkCenter]],'Resource Info'!A:B,2,FALSE), "0") -> LSV Line 1 | L21: =IFERROR(VLOOKUP(TableToday[[#This Row],[Pack Line]],'Resource Info'!B:C,2,FALSE),"0") -> LSV Conditioning | M21: =IF(OR(TableToday[[#This Row],[Department]]="SSV TREATPACK", TableToday[[#This Row],[Department]]="LSV TREATPACK"), VLOOKUP(TableToday[[#This Row],[Pack Line]],'Packaging Rates'!$A$2:$C$9,3,FALSE)+ (TableToday[[#This Row],[Output Qty]]/(VLOOKUP(TableToday[[#This Row],[Pack Line]],'Packaging Rates'!$A$2:$C$9,2,FALSE))),"") | N21: =IF(OR(TableToday[[#This Row],[Department]]="SSV TREATPACK", TableToday[[#This Row],[Department]]="LSV TREATPACK"),8,"")
A22: =TRIM(LEFT(B22,4)) -> PECO | B22: PECO SP704-3-8 SNP RDY ZZZ BK KG | C22: 1002266889 | D22: 36310 | E22: KG | F22: 46265 | G22: PECO PEA RAW RDY Ln2 INT | H22: 7 | I22: ="NEW" -> NEW | J22: =IFERROR(VLOOKUP(TableToday[[#This Row],[Prod. Order]],Components!A:B,2,FALSE), "0") -> LSVLN1 | K22: =IFERROR(VLOOKUP(TableToday[[#This Row],[WorkCenter]],'Resource Info'!A:B,2,FALSE), "0") -> LSV Line 1 | L22: =IFERROR(VLOOKUP(TableToday[[#This Row],[Pack Line]],'Resource Info'!B:C,2,FALSE),"0") -> LSV Conditioning | M22: =IF(OR(TableToday[[#This Row],[Department]]="SSV TREATPACK", TableToday[[#This Row],[Department]]="LSV TREATPACK"), VLOOKUP(TableToday[[#This Row],[Pack Line]],'Packaging Rates'!$A$2:$C$9,3,FALSE)+ (TableToday[[#This Row],[Output Qty]]/(VLOOKUP(TableToday[[#This Row],[Pack Line]],'Packaging Rates'!$A$2:$C$9,2,FALSE))),"") | N22: =IF(OR(TableToday[[#This Row],[Department]]="SSV TREATPACK", TableToday[[#This Row],[Department]]="LSV TREATPACK"),8,"")
A23: =TRIM(LEFT(B23,4)) -> PECO | B23: PECO SP704-3-8 SNP RDY ZZZ BK KG | C23: 1002266350 | D23: 3390 | E23: KG | F23: 46274 | G23: PECO PEA RAW RDY Ln2 INT | H23: 7 | I23: ="NEW" -> NEW | J23: =IFERROR(VLOOKUP(TableToday[[#This Row],[Prod. Order]],Components!A:B,2,FALSE), "0") -> LSVLN1 | K23: =IFERROR(VLOOKUP(TableToday[[#This Row],[WorkCenter]],'Resource Info'!A:B,2,FALSE), "0") -> LSV Line 1 | L23: =IFERROR(VLOOKUP(TableToday[[#This Row],[Pack Line]],'Resource Info'!B:C,2,FALSE),"0") -> LSV Conditioning | M23: =IF(OR(TableToday[[#This Row],[Department]]="SSV TREATPACK", TableToday[[#This Row],[Department]]="LSV TREATPACK"), VLOOKUP(TableToday[[#This Row],[Pack Line]],'Packaging Rates'!$A$2:$C$9,3,FALSE)+ (TableToday[[#This Row],[Output Qty]]/(VLOOKUP(TableToday[[#This Row],[Pack Line]],'Packaging Rates'!$A$2:$C$9,2,FALSE))),"") | N23: =IF(OR(TableToday[[#This Row],[Department]]="SSV TREATPACK", TableToday[[#This Row],[Department]]="LSV TREATPACK"),8,"")
A24: =TRIM(LEFT(B24,4)) -> PECO | B24: PECO SP704-3-8 SNP RDY ZZZ BK KG | C24: 1002266356 | D24: 14930 | E24: KG | F24: 46274 | G24: PECO PEA RAW RDY Ln2 INT | H24: 7 | I24: ="NEW" -> NEW | J24: =IFERROR(VLOOKUP(TableToday[[#This Row],[Prod. Order]],Components!A:B,2,FALSE), "0") -> LSVLN1 | K24: =IFERROR(VLOOKUP(TableToday[[#This Row],[WorkCenter]],'Resource Info'!A:B,2,FALSE), "0") -> LSV Line 1 | L24: =IFERROR(VLOOKUP(TableToday[[#This Row],[Pack Line]],'Resource Info'!B:C,2,FALSE),"0") -> LSV Conditioning | M24: =IF(OR(TableToday[[#This Row],[Department]]="SSV TREATPACK", TableToday[[#This Row],[Department]]="LSV TREATPACK"), VLOOKUP(TableToday[[#This Row],[Pack Line]],'Packaging Rates'!$A$2:$C$9,3,FALSE)+ (TableToday[[#This Row],[Output Qty]]/(VLOOKUP(TableToday[[#This Row],[Pack Line]],'Packaging Rates'!$A$2:$C$9,2,FALSE))),"") | N24: =IF(OR(TableToday[[#This Row],[Department]]="SSV TREATPACK", TableToday[[#This Row],[Department]]="LSV TREATPACK"),8,"")
A25: =TRIM(LEFT(B25,4)) -> BSCO | B25: BSCO ABACUS RDY ZZZ BK KS | C25: 100028768 | D25: 317 | E25: KG | F25: 46314 | G25: Priority 2. HWT light for Xanthomonas po | I25: ="NEW" -> NEW | J25: =IFERROR(VLOOKUP(TableToday[[#This Row],[Prod. Order]],Components!A:B,2,FALSE), "0") -> PASSHLTH | K25: =IFERROR(VLOOKUP(TableToday[[#This Row],[WorkCenter]],'Resource Info'!A:B,2,FALSE), "0") -> Seed Health | L25: =IFERROR(VLOOKUP(TableToday[[#This Row],[Pack Line]],'Resource Info'!B:C,2,FALSE),"0") -> Seed Health | M25: =IF(OR(TableToday[[#This Row],[Department]]="SSV TREATPACK", TableToday[[#This Row],[Department]]="LSV TREATPACK"), VLOOKUP(TableToday[[#This Row],[Pack Line]],'Packaging Rates'!$A$2:$C$9,3,FALSE)+ (TableToday[[#This Row],[Output Qty]]/(VLOOKUP(TableToday[[#This Row],[Pack Line]],'Packaging Rates'!$A$2:$C$9,2,FALSE))),"") | N25: =IF(OR(TableToday[[#This Row],[Department]]="SSV TREATPACK", TableToday[[#This Row],[Department]]="LSV TREATPACK"),8,"")
A26: =TRIM(LEFT(B26,4)) -> WACO | B26: WACO MELODY SDL RDY ZZZ BK KS | C26: 1002298024 | D26: 256 | E26: KG | F26: 46266 | G26: WACO RDY LN3 SDL INT | I26: ="NEW" -> NEW | J26: =IFERROR(VLOOKUP(TableToday[[#This Row],[Prod. Order]],Components!A:B,2,FALSE), "0") -> SSVLN3 | K26: =IFERROR(VLOOKUP(TableToday[[#This Row],[WorkCenter]],'Resource Info'!A:B,2,FALSE), "0") -> SSV Line 3 | L26: =IFERROR(VLOOKUP(TableToday[[#This Row],[Pack Line]],'Resource Info'!B:C,2,FALSE),"0") -> SSV Conditioning | M26: =IF(OR(TableToday[[#This Row],[Department]]="SSV TREATPACK", TableToday[[#This Row],[Department]]="LSV TREATPACK"), VLOOKUP(TableToday[[#This Row],[Pack Line]],'Packaging Rates'!$A$2:$C$9,3,FALSE)+ (TableToday[[#This Row],[Output Qty]]/(VLOOKUP(TableToday[[#This Row],[Pack Line]],'Packaging Rates'!$A$2:$C$9,2,FALSE))),"") | N26: =IF(OR(TableToday[[#This Row],[Department]]="SSV TREATPACK", TableToday[[#This Row],[Department]]="LSV TREATPACK"),8,"")
A27: =TRIM(LEFT(B27,4)) -> WCCO | B27: WCCO FABIOLA RDY ZZZ BK KS | C27: 100028467 | D27: 752.5 | E27: KG | F27: 46311 | G27: Priority 2. HWT light for Xanthomonas po | I27: ="NEW" -> NEW | J27: =IFERROR(VLOOKUP(TableToday[[#This Row],[Prod. Order]],Components!A:B,2,FALSE), "0") -> PASSHLTH | K27: =IFERROR(VLOOKUP(TableToday[[#This Row],[WorkCenter]],'Resource Info'!A:B,2,FALSE), "0") -> Seed Health | L27: =IFERROR(VLOOKUP(TableToday[[#This Row],[Pack Line]],'Resource Info'!B:C,2,FALSE),"0") -> Seed Health | M27: =IF(OR(TableToday[[#This Row],[Department]]="SSV TREATPACK", TableToday[[#This Row],[Department]]="LSV TREATPACK"), VLOOKUP(TableToday[[#This Row],[Pack Line]],'Packaging Rates'!$A$2:$C$9,3,FALSE)+ (TableToday[[#This Row],[Output Qty]]/(VLOOKUP(TableToday[[#This Row],[Pack Line]],'Packaging Rates'!$A$2:$C$9,2,FALSE))),"") | N27: =IF(OR(TableToday[[#This Row],[Department]]="SSV TREATPACK", TableToday[[#This Row],[Department]]="LSV TREATPACK"),8,"")
A28: =TRIM(LEFT(B28,4)) -> WACO | B28: WACO SWEET GEM SDL RDY ZZZ BK KS | C28: 1002303255 | D28: 145 | E28: KG | F28: 46290 | G28: WACO RDY LN3 SDL INT | I28: ="NEW" -> NEW | J28: =IFERROR(VLOOKUP(TableToday[[#This Row],[Prod. Order]],Components!A:B,2,FALSE), "0") -> SSVLN6 | K28: =IFERROR(VLOOKUP(TableToday[[#This Row],[WorkCenter]],'Resource Info'!A:B,2,FALSE), "0") -> SSV Line 6 | L28: =IFERROR(VLOOKUP(TableToday[[#This Row],[Pack Line]],'Resource Info'!B:C,2,FALSE),"0") -> SSV Conditioning | M28: =IF(OR(TableToday[[#This Row],[Department]]="SSV TREATPACK", TableToday[[#This Row],[Department]]="LSV TREATPACK"), VLOOKUP(TableToday[[#This Row],[Pack Line]],'Packaging Rates'!$A$2:$C$9,3,FALSE)+ (TableToday[[#This Row],[Output Qty]]/(VLOOKUP(TableToday[[#This Row],[Pack Line]],'Packaging Rates'!$A$2:$C$9,2,FALSE))),"") | N28: =IF(OR(TableToday[[#This Row],[Department]]="SSV TREATPACK", TableToday[[#This Row],[Department]]="LSV TREATPACK"),8,"")
A29: =TRIM(LEFT(B29,4)) -> BRCO | B29: BRCO SBB003 RDY ZZZ BK KS | C29: 100028679 | D29: 90 | E29: KG | F29: 46255 | G29: HWT heavy for Xanthomonas positive | I29: ="NEW" -> NEW | J29: =IFERROR(VLOOKUP(TableToday[[#This Row],[Prod. Order]],Components!A:B,2,FALSE), "0") -> PASSHLTH | K29: =IFERROR(VLOOKUP(TableToday[[#This Row],[WorkCenter]],'Resource Info'!A:B,2,FALSE), "0") -> Seed Health | L29: =IFERROR(VLOOKUP(TableToday[[#This Row],[Pack Line]],'Resource Info'!B:C,2,FALSE),"0") -> Seed Health | M29: =IF(OR(TableToday[[#This Row],[Department]]="SSV TREATPACK", TableToday[[#This Row],[Department]]="LSV TREATPACK"), VLOOKUP(TableToday[[#This Row],[Pack Line]],'Packaging Rates'!$A$2:$C$9,3,FALSE)+ (TableToday[[#This Row],[Output Qty]]/(VLOOKUP(TableToday[[#This Row],[Pack Line]],'Packaging Rates'!$A$2:$C$9,2,FALSE))),"") | N29: =IF(OR(TableToday[[#This Row],[Department]]="SSV TREATPACK", TableToday[[#This Row],[Department]]="LSV TREATPACK"),8,"")
A30: =TRIM(LEFT(B30,4)) -> SQBS | B30: SQBS PP614 RDY ZZZ BK KS | C30: 1002306428 | D30: 25.06 | E30: KG | F30: 46297 | G30: SQBS RAW RDY INT | I30: ="NEW" -> NEW | J30: =IFERROR(VLOOKUP(TableToday[[#This Row],[Prod. Order]],Components!A:B,2,FALSE), "0") -> SSVLN5 | K30: =IFERROR(VLOOKUP(TableToday[[#This Row],[WorkCenter]],'Resource Info'!A:B,2,FALSE), "0") -> SSV Line 5 | L30: =IFERROR(VLOOKUP(TableToday[[#This Row],[Pack Line]],'Resource Info'!B:C,2,FALSE),"0") -> SSV Conditioning | M30: =IF(OR(TableToday[[#This Row],[Department]]="SSV TREATPACK", TableToday[[#This Row],[Department]]="LSV TREATPACK"), VLOOKUP(TableToday[[#This Row],[Pack Line]],'Packaging Rates'!$A$2:$C$9,3,FALSE)+ (TableToday[[#This Row],[Output Qty]]/(VLOOKUP(TableToday[[#This Row],[Pack Line]],'Packaging Rates'!$A$2:$C$9,2,FALSE))),"") | N30: =IF(OR(TableToday[[#This Row],[Department]]="SSV TREATPACK", TableToday[[#This Row],[Department]]="LSV TREATPACK"),8,"")
A31: =TRIM(LEFT(B31,4)) -> WABS | B31: WABS 1W027 SDD RDY ZZZ BK KS | C31: 1002302356 | D31: 31.23 | E31: KG | F31: 46287 | G31: WABS RAW RDY INT | I31: ="NEW" -> NEW | J31: =IFERROR(VLOOKUP(TableToday[[#This Row],[Prod. Order]],Components!A:B,2,FALSE), "0") -> SSVLN5 | K31: =IFERROR(VLOOKUP(TableToday[[#This Row],[WorkCenter]],'Resource Info'!A:B,2,FALSE), "0") -> SSV Line 5 | L31: =IFERROR(VLOOKUP(TableToday[[#This Row],[Pack Line]],'Resource Info'!B:C,2,FALSE),"0") -> SSV Conditioning | M31: =IF(OR(TableToday[[#This Row],[Department]]="SSV TREATPACK", TableToday[[#This Row],[Department]]="LSV TREATPACK"), VLOOKUP(TableToday[[#This Row],[Pack Line]],'Packaging Rates'!$A$2:$C$9,3,FALSE)+ (TableToday[[#This Row],[Output Qty]]/(VLOOKUP(TableToday[[#This Row],[Pack Line]],'Packaging Rates'!$A$2:$C$9,2,FALSE))),"") | N31: =IF(OR(TableToday[[#This Row],[Department]]="SSV TREATPACK", TableToday[[#This Row],[Department]]="LSV TREATPACK"),8,"")
A32: =TRIM(LEFT(B32,4)) -> WACO | B32: WACO FASCINATION SDL RDY ZZZ BK KS | C32: 300102396 | D32: 1200 | E32: KS | F32: 46308 | G32: Please repair germ from 89 to above 90%. | I32: ="NEW" -> NEW | J32: =IFERROR(VLOOKUP(TableToday[[#This Row],[Prod. Order]],Components!A:B,2,FALSE), "0") -> SSVRPR5 | K32: =IFERROR(VLOOKUP(TableToday[[#This Row],[WorkCenter]],'Resource Info'!A:B,2,FALSE), "0") -> SSV Line 5 Repair | L32: =IFERROR(VLOOKUP(TableToday[[#This Row],[Pack Line]],'Resource Info'!B:C,2,FALSE),"0") -> SSV Conditioning | M32: =IF(OR(TableToday[[#This Row],[Department]]="SSV TREATPACK", TableToday[[#This Row],[Department]]="LSV TREATPACK"), VLOOKUP(TableToday[[#This Row],[Pack Line]],'Packaging Rates'!$A$2:$C$9,3,FALSE)+ (TableToday[[#This Row],[Output Qty]]/(VLOOKUP(TableToday[[#This Row],[Pack Line]],'Packaging Rates'!$A$2:$C$9,2,FALSE))),"") | N32: =IF(OR(TableToday[[#This Row],[Department]]="SSV TREATPACK", TableToday[[#This Row],[Department]]="LSV TREATPACK"),8,"")
A33: =TRIM(LEFT(B33,4)) -> WACO | B33: WACO FASCINATION SDL RDY ZZZ BK KS | C33: 300102397 | D33: 1750 | E33: KS | F33: 46308 | G33: Please repair germ from 89 to above 90%. | I33: ="NEW" -> NEW | J33: =IFERROR(VLOOKUP(TableToday[[#This Row],[Prod. Order]],Components!A:B,2,FALSE), "0") -> SSVRPR5 | K33: =IFERROR(VLOOKUP(TableToday[[#This Row],[WorkCenter]],'Resource Info'!A:B,2,FALSE), "0") -> SSV Line 5 Repair | L33: =IFERROR(VLOOKUP(TableToday[[#This Row],[Pack Line]],'Resource Info'!B:C,2,FALSE),"0") -> SSV Conditioning | M33: =IF(OR(TableToday[[#This Row],[Department]]="SSV TREATPACK", TableToday[[#This Row],[Department]]="LSV TREATPACK"), VLOOKUP(TableToday[[#This Row],[Pack Line]],'Packaging Rates'!$A$2:$C$9,3,FALSE)+ (TableToday[[#This Row],[Output Qty]]/(VLOOKUP(TableToday[[#This Row],[Pack Line]],'Packaging Rates'!$A$2:$C$9,2,FALSE))),"") | N33: =IF(OR(TableToday[[#This Row],[Department]]="SSV TREATPACK", TableToday[[#This Row],[Department]]="LSV TREATPACK"),8,"")
A34: =TRIM(LEFT(B34,4)) -> WACO | B34: WACO QUETZALI SDD RDY ZZZ BK KS | C34: 1002298227 | D34: 1380 | E34: KG | F34: 46266 | G34: WACO RDY Ln1 SDD INT | I34: ="NEW" -> NEW | J34: =IFERROR(VLOOKUP(TableToday[[#This Row],[Prod. Order]],Components!A:B,2,FALSE), "0") -> SSVLN3 | K34: =IFERROR(VLOOKUP(TableToday[[#This Row],[WorkCenter]],'Resource Info'!A:B,2,FALSE), "0") -> SSV Line 3 | L34: =IFERROR(VLOOKUP(TableToday[[#This Row],[Pack Line]],'Resource Info'!B:C,2,FALSE),"0") -> SSV Conditioning | M34: =IF(OR(TableToday[[#This Row],[Department]]="SSV TREATPACK", TableToday[[#This Row],[Department]]="LSV TREATPACK"), VLOOKUP(TableToday[[#This Row],[Pack Line]],'Packaging Rates'!$A$2:$C$9,3,FALSE)+ (TableToday[[#This Row],[Output Qty]]/(VLOOKUP(TableToday[[#This Row],[Pack Line]],'Packaging Rates'!$A$2:$C$9,2,FALSE))),"") | N34: =IF(OR(TableToday[[#This Row],[Department]]="SSV TREATPACK", TableToday[[#This Row],[Department]]="LSV TREATPACK"),8,"")
A35: =TRIM(LEFT(B35,4)) -> WACO | B35: WACO QUETZALI SDD RDY ZZZ BK KS | C35: 1002305699 | D35: 1600 | E35: KG | F35: 46303 | G35: WACO RDY Ln1 SDD INT | I35: ="NEW" -> NEW | J35: =IFERROR(VLOOKUP(TableToday[[#This Row],[Prod. Order]],Components!A:B,2,FALSE), "0") -> SSVLN3 | K35: =IFERROR(VLOOKUP(TableToday[[#This Row],[WorkCenter]],'Resource Info'!A:B,2,FALSE), "0") -> SSV Line 3 | L35: =IFERROR(VLOOKUP(TableToday[[#This Row],[Pack Line]],'Resource Info'!B:C,2,FALSE),"0") -> SSV Conditioning | M35: =IF(OR(TableToday[[#This Row],[Department]]="SSV TREATPACK", TableToday[[#This Row],[Department]]="LSV TREATPACK"), VLOOKUP(TableToday[[#This Row],[Pack Line]],'Packaging Rates'!$A$2:$C$9,3,FALSE)+ (TableToday[[#This Row],[Output Qty]]/(VLOOKUP(TableToday[[#This Row],[Pack Line]],'Packaging Rates'!$A$2:$C$9,2,FALSE))),"") | N35: =IF(OR(TableToday[[#This Row],[Department]]="SSV TREATPACK", TableToday[[#This Row],[Department]]="LSV TREATPACK"),8,"")
A36: =TRIM(LEFT(B36,4)) -> WACO | B36: WACO CAPTIVATION SDL RDY ZZZ BK KS | C36: 1002303257 | D36: 220 | E36: KG | F36: 46290 | G36: WACO RDY LN3 SDL INT | I36: ="NEW" -> NEW | J36: =IFERROR(VLOOKUP(TableToday[[#This Row],[Prod. Order]],Components!A:B,2,FALSE), "0") -> SSVLN3 | K36: =IFERROR(VLOOKUP(TableToday[[#This Row],[WorkCenter]],'Resource Info'!A:B,2,FALSE), "0") -> SSV Line 3 | L36: =IFERROR(VLOOKUP(TableToday[[#This Row],[Pack Line]],'Resource Info'!B:C,2,FALSE),"0") -> SSV Conditioning | M36: =IF(OR(TableToday[[#This Row],[Department]]="SSV TREATPACK", TableToday[[#This Row],[Department]]="LSV TREATPACK"), VLOOKUP(TableToday[[#This Row],[Pack Line]],'Packaging Rates'!$A$2:$C$9,3,FALSE)+ (TableToday[[#This Row],[Output Qty]]/(VLOOKUP(TableToday[[#This Row],[Pack Line]],'Packaging Rates'!$A$2:$C$9,2,FALSE))),"") | N36: =IF(OR(TableToday[[#This Row],[Department]]="SSV TREATPACK", TableToday[[#This Row],[Department]]="LSV TREATPACK"),8,"")
... A49: =TRIM(LEFT(B49,4)) -> SQCO | B49: SQCO SPINE BEAUTY RDY ZZZ BK KS | C49: 1002300975 | D49: 171.843 | E49: KG | F49: 46280 | G49: SQCO RAW RDY Ln1 INT | I49: ="NEW" -> NEW | J49: =IFERROR(VLOOKUP(TableToday[[#This Row],[Prod. Order]],Components!A:B,2,FALSE), "0") -> SSVLN6 | K49: =IFERROR(VLOOKUP(TableToday[[#This Row],[WorkCenter]],'Resource Info'!A:B,2,FALSE), "0") -> SSV Line 6 | L49: =IFERROR(VLOOKUP(TableToday[[#This Row],[Pack Line]],'Resource Info'!B:C,2,FALSE),"0") -> SSV Conditioning | M49: =IF(OR(TableToday[[#This Row],[Department]]="SSV TREATPACK", TableToday[[#This Row],[Department]]="LSV TREATPACK"), VLOOKUP(TableToday[[#This Row],[Pack Line]],'Packaging Rates'!$A$2:$C$9,3,FALSE)+ (TableToday[[#This Row],[Output Qty]]/(VLOOKUP(TableToday[[#This Row],[Pack Line]],'Packaging Rates'!$A$2:$C$9,2,FALSE))),"") | N49: =IF(OR(TableToday[[#This Row],[Department]]="SSV TREATPACK", TableToday[[#This Row],[Department]]="LSV TREATPACK"),8,"")
A50: =TRIM(LEFT(B50,4)) -> PECO | B50: PECO SL3123 SNP RDY ZZZ BK KG | C50: 1002266120 | D50: 15020 | E50: KG | F50: 46233 | G50: PECO PEA RAW RDY Ln2 INT | H50: 1 | I50: ="NEW" -> NEW | J50: =IFERROR(VLOOKUP(TableToday[[#This Row],[Prod. Order]],Components!A:B,2,FALSE), "0") -> LSVLN2 | K50: =IFERROR(VLOOKUP(TableToday[[#This Row],[WorkCenter]],'Resource Info'!A:B,2,FALSE), "0") -> LSV Line 2 | L50: =IFERROR(VLOOKUP(TableToday[[#This Row],[Pack Line]],'Resource Info'!B:C,2,FALSE),"0") -> LSV Conditioning | M50: =IF(OR(TableToday[[#This Row],[Department]]="SSV TREATPACK", TableToday[[#This Row],[Department]]="LSV TREATPACK"), VLOOKUP(TableToday[[#This Row],[Pack Line]],'Packaging Rates'!$A$2:$C$9,3,FALSE)+ (TableToday[[#This Row],[Output Qty]]/(VLOOKUP(TableToday[[#This Row],[Pack Line]],'Packaging Rates'!$A$2:$C$9,2,FALSE))),"") | N50: =IF(OR(TableToday[[#This Row],[Department]]="SSV TREATPACK", TableToday[[#This Row],[Department]]="LSV TREATPACK"),8,"")
A51: =TRIM(LEFT(B51,4)) -> BEBS | B51: BEBS HUNTINGTON S RDY ZZZ BK KG | C51: 1002303218 | D51: 1120 | E51: KG | F51: 46384 | G51: BEBS RAW RDY Ln2 INT | H51: 5 | I51: ="NEW" -> NEW | J51: =IFERROR(VLOOKUP(TableToday[[#This Row],[Prod. Order]],Components!A:B,2,FALSE), "0") -> LSVLN2 | K51: =IFERROR(VLOOKUP(TableToday[[#This Row],[WorkCenter]],'Resource Info'!A:B,2,FALSE), "0") -> LSV Line 2 | L51: =IFERROR(VLOOKUP(TableToday[[#This Row],[Pack Line]],'Resource Info'!B:C,2,FALSE),"0") -> LSV Conditioning | M51: =IF(OR(TableToday[[#This Row],[Department]]="SSV TREATPACK", TableToday[[#This Row],[Department]]="LSV TREATPACK"), VLOOKUP(TableToday[[#This Row],[Pack Line]],'Packaging Rates'!$A$2:$C$9,3,FALSE)+ (TableToday[[#This Row],[Output Qty]]/(VLOOKUP(TableToday[[#This Row],[Pack Line]],'Packaging Rates'!$A$2:$C$9,2,FALSE))),"") | N51: =IF(OR(TableToday[[#This Row],[Department]]="SSV TREATPACK", TableToday[[#This Row],[Department]]="LSV TREATPACK"),8,"")
A52: =TRIM(LEFT(B52,4)) -> BEBS | B52: BEBS HUNTINGTON T RDY ZZZ BK KG | C52: 1002303211 | D52: 28890 | E52: KG | F52: 46384 | G52: BEBS RAW RDY Ln2 INT | H52: 5 | I52: ="NEW" -> NEW | J52: =IFERROR(VLOOKUP(TableToday[[#This Row],[Prod. Order]],Components!A:B,2,FALSE), "0") -> LSVLN2 | K52: =IFERROR(VLOOKUP(TableToday[[#This Row],[WorkCenter]],'Resource Info'!A:B,2,FALSE), "0") -> LSV Line 2 | L52: =IFERROR(VLOOKUP(TableToday[[#This Row],[Pack Line]],'Resource Info'!B:C,2,FALSE),"0") -> LSV Conditioning | M52: =IF(OR(TableToday[[#This Row],[Department]]="SSV TREATPACK", TableToday[[#This Row],[Department]]="LSV TREATPACK"), VLOOKUP(TableToday[[#This Row],[Pack Line]],'Packaging Rates'!$A$2:$C$9,3,FALSE)+ (TableToday[[#This Row],[Output Qty]]/(VLOOKUP(TableToday[[#This Row],[Pack Line]],'Packaging Rates'!$A$2:$C$9,2,FALSE))),"") | N52: =IF(OR(TableToday[[#This Row],[Department]]="SSV TREATPACK", TableToday[[#This Row],[Department]]="LSV TREATPACK"),8,"")
...

Sheet Components
A1: All Components
A2: Process Order | B2: Resource
A3: 100028467 | B3: PASSHLTH
A4: 100028679 | B4: PASSHLTH
A5: 100028680 | B5: PASSHLTH
A6: 100028681 | B6: PASSHLTH
A7: 100028748 | B7: SSVLN5
A8: 100028749 | B8: PASSHLTH
A9: 100028750 | B9: PASSHLTH
A10: 100028768 | B10: PASSHLTH
A11: 120000902 | B11: LSVLN2
A12: 120000903 | B12: LSVLN2
A13: 120000904 | B13: LSVLN2
A14: 300097077 | B14: LSVGRVTY
... A216: 2400008280 | B216: LSVGRVTY

Sheet LSV Treatpack
A1: Crop | B1: Material Description | C1: Prod. Order | D1: Output Qty | E1: UOM | F1: Scheduled Finish Date (SAP) | G1: Notes: | H1: PO Status | I1: WorkCenter | J1: Pack Line | K1: Department | L1: Hours | M1: Capacity

Sheet SSV Treatpack
A1: Crop | B1: Material Description | C1: Prod. Order | D1: Output Qty | E1: UOM | F1: Scheduled Finish Date (SAP) | G1: Notes: | H1: PO Status | I1: WorkCenter | J1: Pack Line | K1: Department | L1: Hours | M1: Capacity

Sheet Seed Health
A1: Crop | B1: Material Description | C1: Prod. Order | D1: Output Qty | E1: UOM | F1: Scheduled Finish Date (SAP) | G1: Notes: | H1: Priority | I1: PO Status | J1: WorkCenter | K1: Pack Line | L1: Department | M1: Hours | N1: Capacity
A2: WCCO | B2: WCCO FABIOLA RDY ZZZ BK KS | C2: 100028467 | D2: 752.5 | E2: KG | F2: 46311 | G2: Priority 2. HWT light for Xanthomonas po | I2: NEW | J2: PASSHLTH | K2: Seed Health | L2: Seed Health
A3: BSCO | B3: BSCO ABACUS RDY ZZZ BK KS | C3: 100028768 | D3: 317 | E3: KG | F3: 46314 | G3: Priority 2. HWT light for Xanthomonas po | I3: NEW | J3: PASSHLTH | K3: Seed Health | L3: Seed Health
A4: BRCO | B4: BRCO SBB003 RDY ZZZ BK KS | C4: 100028679 | D4: 90 | E4: KG | F4: 46255 | G4: HWT heavy for Xanthomonas positive | I4: NEW | J4: PASSHLTH | K4: Seed Health | L4: Seed Health
A5: CFCO | B5: CFCO SGC3131 RDY ZZZ BK KS | C5: 100028681 | D5: 19 | E5: KG | F5: 46260 | G5: HWT light for Xanthomonas positive | I5: NEW | J5: PASSHLTH | K5: Seed Health | L5: Seed Health
A6: CACO | B6: CACO SYCAMORE SWE RDH ZZZ BK KS | C6: 1002307955 | D6: 15 | E6: KG | F6: 46310 | G6: CACO RAW RDH INT | I6: NEW | J6: PASSHLTH | K6: Seed Health | L6: Seed Health
A7: CACO | B7: CACO SAGUARO SWE RDH ZZZ BK KS | C7: 1002301913 | D7: 15 | E7: KG | F7: 46290 | G7: CACO RAW RDH INT | I7: NEW | J7: PASSHLTH | K7: Seed Health | L7: Seed Health
A8: CACO | B8: CACO MEXICA HOT RDH ZZZ BK KS | C8: 1002297494 | D8: 15 | E8: KG | F8: 46283 | G8: CACO RAW RDH INT | I8: NEW | J8: PASSHLTH | K8: Seed Health | L8: Seed Health
A9: CACO | B9: CACO MEXICA HOT RDH ZZZ BK KS | C9: 1002297548 | D9: 14 | E9: KG | F9: 46283 | G9: CACO RAW RDH INT | I9: NEW | J9: PASSHLTH | K9: Seed Health | L9: Seed Health
A10: CACO | B10: CACO MEXICA HOT RDH ZZZ BK KS | C10: 1002297502 | D10: 14 | E10: KG | F10: 46288 | G10: CACO RAW RDH INT | I10: NEW | J10: PASSHLTH | K10: Seed Health | L10: Seed Health
A11: CACO | B11: CACO MEXICA HOT RDH ZZZ BK KS | C11: 1002297504 | D11: 14 | E11: KG | F11: 46288 | G11: CACO RAW RDH INT | I11: NEW | J11: PASSHLTH | K11: Seed Health | L11: Seed Health
A12: CACO | B12: CACO MEXICA HOT RDH ZZZ BK KS | C12: 1002297505 | D12: 14 | E12: KG | F12: 46288 | G12: CACO RAW RDH INT | I12: NEW | J12: PASSHLTH | K12: Seed Health | L12: Seed Health
A13: CACO | B13: CACO MEXICA HOT RDH ZZZ BK KS | C13: 1002297546 | D13: 14 | E13: KG | F13: 46288 | G13: CACO RAW RDH INT | I13: NEW | J13: PASSHLTH | K13: Seed Health | L13: Seed Health
... A44: TOBS | B44: TOBS TP228 PRC RDY ZZZ BK KS | C44: 1002154380 | D44: 0.2 | E44: KG | F44: 46181 | G44: TOBS RAW RDY INT | I44: NEW | J44: PASSHLTH | K44: Seed Health | L44: Seed Health

Sheet SSV Line 3
A1: Crop | B1: Material Description | C1: Prod. Order | D1: Output Qty | E1: UOM | F1: Scheduled Finish Date (SAP) | G1: Notes: | H1: Priority | I1: PO Status | J1: WorkCenter | K1: Pack Line | L1: Department | M1: Hours | N1: Capacity
A2: WACO | B2: WACO SP-7 SDD RDY ZZZ BK KS | C2: 1002300828 | D2: 4500 | E2: KG | F2: 46279 | G2: WACO RDY Ln1 SDD INT | I2: NEW | J2: SSVLN3 | K2: SSV Line 3 | L2: SSV Conditioning
A3: WACO | B3: WACO QUETZALI SDD RDY ZZZ BK KS | C3: 1002305699 | D3: 1600 | E3: KG | F3: 46303 | G3: WACO RDY Ln1 SDD INT | I3: NEW | J3: SSVLN3 | K3: SSV Line 3 | L3: SSV Conditioning
A4: WACO | B4: WACO QUETZALI SDD RDY ZZZ BK KS | C4: 1002298227 | D4: 1380 | E4: KG | F4: 46266 | G4: WACO RDY Ln1 SDD INT | I4: NEW | J4: SSVLN3 | K4: SSV Line 3 | L4: SSV Conditioning
A5: WCCO | B5: WCCO XIANGAN011 RDY ZZZ BK KS | C5: 1002309118 | D5: 727 | E5: KG | F5: 46300 | G5: RUSH - Priority 1. For Export to NL | I5: NEW | J5: SSVLN3 | K5: SSV Line 3 | L5: SSV Conditioning
A6: WACO | B6: WACO EXCURSION SDL RDY ZZZ BK KS | C6: 1002302679 | D6: 500 | E6: KG | F6: 46282 | G6: WACO RDY LN3 SDL INT | I6: NEW | J6: SSVLN3 | K6: SSV Line 3 | L6: SSV Conditioning
A7: WCCO | B7: WCCO KEPLER RDY ZZZ BK KS | C7: 1002309119 | D7: 375 | E7: KG | F7: 46311 | G7: Priority 2. For Export to NL | I7: NEW | J7: SSVLN3 | K7: SSV Line 3 | L7: SSV Conditioning
A8: SQCO | B8: SQCO SPINE BEAUTY RDY ZZZ BK KS | C8: 1002294970 | D8: 330.5 | E8: KG | F8: 46254 | G8: SQCO RAW RDY Ln1 INT | I8: NEW | J8: SSVLN3 | K8: SSV Line 3 | L8: SSV Conditioning
A9: WACO | B9: WACO VIRTUE SDL RDY ZZZ BK KS | C9: 1002303256 | D9: 325 | E9: KG | F9: 46293 | G9: WACO RDY LN3 SDL INT | I9: NEW | J9: SSVLN3 | K9: SSV Line 3 | L9: SSV Conditioning
A10: CFCO | B10: CFCO SPACEDREAM RDY ZZZ BK KS | C10: 300102025 | D10: 308 | E10: KG | F10: 46232 | G10: Please repair for 90% germ to 95% or bet | I10: NEW | J10: SSVRPR3 | K10: SSV Line 3 Repair | L10: SSV Conditioning
A11: WACO | B11: WACO VIRTUE SDL RDY ZZZ BK KS | C11: 1002300829 | D11: 290 | E11: KG | F11: 46280 | G11: WACO RDY LN3 SDL INT | I11: NEW | J11: SSVLN3 | K11: SSV Line 3 | L11: SSV Conditioning
A12: SQCO | B12: SQCO EQUINOX RDY ZZZ BK KS | C12: 1002299671 | D12: 260.5 | E12: KG | F12: 46269 | G12: SQCO RAW RDY Ln1 INT | I12: NEW | J12: SSVLN3 | K12: SSV Line 3 | L12: SSV Conditioning
A13: WACO | B13: WACO MELODY SDL RDY ZZZ BK KS | C13: 1002298024 | D13: 256 | E13: KG | F13: 46266 | G13: WACO RDY LN3 SDL INT | I13: NEW | J13: SSVLN3 | K13: SSV Line 3 | L13: SSV Conditioning
... A17: SQCO | B17: SQCO SPINE BEAUTY RDY ZZZ BK KS | C17: 1002300974 | D17: 211.865 | E17: KG | F17: 46279 | G17: SQCO RAW RDY Ln1 INT | I17: NEW | J17: SSVLN3 | K17: SSV Line 3 | L17: SSV Conditioning

Sheet SSV Line 5
A1: Crop | B1: Material Description | C1: Prod. Order | D1: Output Qty | E1: UOM | F1: Scheduled Finish Date (SAP) | G1: Notes: | H1: Priority | I1: PO Status | J1: WorkCenter | K1: Pack Line | L1: Department | M1: Hours | N1: Capacity
A2: WACO | B2: WACO FASCINATION SDL RDY ZZZ BK KS | C2: 300102397 | D2: 1750 | E2: KS | F2: 46308 | G2: Please repair germ from 89 to above 90%. | I2: NEW | J2: SSVRPR5 | K2: SSV Line 5 Repair | L2: SSV Conditioning
A3: SQCO | B3: SQCO BACANORA RDY ZZZ BK KS | C3: 100028748 | D3: 1630.237 | E3: KS | F3: 46282 | G3: Germ repair for 79% to 85% or above | I3: NEW | J3: SSVLN5 | K3: SSV Line 5 | L3: SSV Conditioning
A4: WACO | B4: WACO EXCURSION SDL RDY ZZZ BK KS | C4: 300102387 | D4: 1500 | E4: KS | F4: 46300 | G4: Please repair germ from 84 to above 90%. | I4: NEW | J4: SSVLN5 | K4: SSV Line 5 | L4: SSV Conditioning
A5: WACO | B5: WACO BLACK JACK SDL RDY ZZZ BK KS | C5: 300102399 | D5: 1400 | E5: KS | F5: 46308 | G5: Please repair germ from 80.75 to above 9 | I5: NEW | J5: SSVRPR5 | K5: SSV Line 5 Repair | L5: SSV Conditioning
A6: WACO | B6: WACO FASCINATION SDL RDY ZZZ BK KS | C6: 300102396 | D6: 1200 | E6: KS | F6: 46308 | G6: Please repair germ from 89 to above 90%. | I6: NEW | J6: SSVRPR5 | K6: SSV Line 5 Repair | L6: SSV Conditioning
A7: WACO | B7: WACO EXCURSION SDL RDY ZZZ BK KS | C7: 300102400 | D7: 1200 | E7: KS | F7: 46308 | G7: Please repair from 89 to above 90%. | I7: NEW | J7: SSVRPR5 | K7: SSV Line 5 Repair | L7: SSV Conditioning
A8: WACO | B8: WACO JAVELIN SDL RDY ZZZ BK KS | C8: 300102395 | D8: 1150 | E8: KS | F8: 46308 | G8: Please repair germ from 85.25 to above 9 | I8: NEW | J8: SSVRPR5 | K8: SSV Line 5 Repair | L8: SSV Conditioning
A9: WACO | B9: WACO VIRTUE SDL RDY ZZZ BK KS | C9: 300102392 | D9: 1150 | E9: KS | F9: 46308 | G9: Please repair germ from 86.25 to above 9 | I9: NEW | J9: SSVRPR5 | K9: SSV Line 5 Repair | L9: SSV Conditioning
A10: WACO | B10: WACO VIRTUE SDL RDY ZZZ BK KS | C10: 300102542 | D10: 900 | E10: KS | F10: 46310 | G10: Please repair germ from 84.75 to above 9 | I10: NEW | J10: SSVRPR5 | K10: SSV Line 5 Repair | L10: SSV Conditioning
A11: WACO | B11: WACO JAVELIN SDL RDY ZZZ BK KS | C11: 300102394 | D11: 750 | E11: KS | F11: 46308 | G11: Please repair germ from 87.75 to above 9 | I11: NEW | J11: SSVRPR5 | K11: SSV Line 5 Repair | L11: SSV Conditioning
A12: WACO | B12: WACO VALOR SDL RDY ZZZ BK KS | C12: 300102388 | D12: 750 | E12: KS | F12: 46300 | G12: Please repair germ from 84.5 to above 90 | I12: NEW | J12: SSVLN5 | K12: SSV Line 5 | L12: SSV Conditioning
A13: WACO | B13: WACO VALOR SDL RDY ZZZ BK KS | C13: 300102398 | D13: 750 | E13: KS | F13: 46308 | G13: Please repair from 87 to above 90%. | I13: NEW | J13: SSVRPR5 | K13: SSV Line 5 Repair | L13: SSV Conditioning
... A43: CABS | B43: CABS P19M4 SWE RDY ZZZ BK KS | C43: 1002301228 | D43: 0.165 | E43: KG | F43: 46287 | G43: CABS RAW RDY INT | I43: NEW | J43: SSVLN5 | K43: SSV Line 5 | L43: SSV Conditioning

Sheet SSV Line 6
A1: Crop | B1: Material Description | C1: Prod. Order | D1: Output Qty | E1: UOM | F1: Scheduled Finish Date (SAP) | G1: Notes: | H1: Priority | I1: PO Status | J1: WorkCenter | K1: Pack Line | L1: Department | M1: Hours | N1: Capacity
A2: TOCO | B2: TOCO QUALI T 99 DET RDH ZZZ BK KS | C2: 300102523 | D2: 2300 | E2: KS | F2: 46290 | G2: TOCO RPR GERM INT | I2: NEW | J2: SSVRPR6 | K2: SSV Line 6 Repair | L2: SSV Conditioning
A3: WACO | B3: WACO POWERHOUSE SDL RDY ZZZ BK KS | C3: 300102119 | D3: 900 | E3: KS | F3: 46241 | G3: Please repair germ to above 90% | I3: NEW | J3: SSVLN6 | K3: SSV Line 6 | L3: SSV Conditioning
A4: WACO | B4: WACO CAPTIVATION SDL RDY ZZZ BK KS | C4: 1002305700 | D4: 175 | E4: KG | F4: 46303 | G4: WACO RDY LN3 SDL INT | I4: NEW | J4: SSVLN6 | K4: SSV Line 6 | L4: SSV Conditioning
A5: SQCO | B5: SQCO PAYROLL RDY ZZZ BK KS | C5: 1002302295 | D5: 172.5 | E5: KG | F5: 46281 | G5: SQCO RAW RDY Ln1 INT | I5: NEW | J5: SSVLN6 | K5: SSV Line 6 | L5: SSV Conditioning
A6: SQCO | B6: SQCO SPINE BEAUTY RDY ZZZ BK KS | C6: 1002300975 | D6: 171.843 | E6: KG | F6: 46280 | G6: SQCO RAW RDY Ln1 INT | I6: NEW | J6: SSVLN6 | K6: SSV Line 6 | L6: SSV Conditioning
A7: MECO | B7: MECO OVATION RDY ZZZ BK KS | C7: 1002302362 | D7: 169 | E7: KG | F7: 46289 | G7: MECO RAW RDY Ln1 INT | I7: NEW | J7: SSVLN6 | K7: SSV Line 6 | L7: SSV Conditioning
A8: SQCO | B8: SQCO GRANDPRIZE RDY ZZZ BK KS | C8: 1002307496 | D8: 146 | E8: KG | F8: 46304 | G8: SQCO RAW RDY Ln1 INT | I8: NEW | J8: SSVLN6 | K8: SSV Line 6 | L8: SSV Conditioning
A9: WACO | B9: WACO SWEET GEM SDL RDY ZZZ BK KS | C9: 1002303255 | D9: 145 | E9: KG | F9: 46290 | G9: WACO RDY LN3 SDL INT | I9: NEW | J9: SSVLN6 | K9: SSV Line 6 | L9: SSV Conditioning
A10: BRCO | B10: BRCO ATRACTIX RDY ZZZ BK KS | C10: 1002292927 | D10: 118.5 | E10: KG | F10: 46280 | G10: BRCO RAW RDY Ln3 INT | I10: NEW | J10: SSVLN6 | K10: SSV Line 6 | L10: SSV Conditioning
A11: SQCO | B11: SQCO PAYROLL RDY ZZZ BK KS | C11: 1002300976 | D11: 111.8 | E11: KG | F11: 46279 | G11: SQCO RAW RDY Ln1 INT | I11: NEW | J11: SSVLN6 | K11: SSV Line 6 | L11: SSV Conditioning
A12: SQCO | B12: SQCO EQUINOX RDY ZZZ BK KS | C12: 1002307491 | D12: 97.5 | E12: KG | F12: 46300 | G12: SQCO RAW RDY Ln1 INT | I12: NEW | J12: SSVLN6 | K12: SSV Line 6 | L12: SSV Conditioning
A13: SQCO | B13: SQCO GRANDPRIZE RDY ZZZ BK KS | C13: 1002307493 | D13: 96.5 | E13: KG | F13: 46301 | G13: SQCO RAW RDY Ln1 INT | I13: NEW | J13: SSVLN6 | K13: SSV Line 6 | L13: SSV Conditioning
... A25: SQBS | B25: SQBS SQ279 RDY ZZZ BK KS | C25: 1002305616 | D25: 55.84 | E25: KG | F25: 46294 | G25: SQBS RAW RDY INT | I25: NEW | J25: SSVLN6 | K25: SSV Line 6 | L25: SSV Conditioning

Sheet SSV Line 7
A1: Crop | B1: Material Description | C1: Prod. Order | D1: Output Qty | E1: UOM | F1: Scheduled Finish Date (SAP) | G1: Notes: | H1: Priority | I1: PO Status | J1: WorkCenter | K1: Pack Line | L1: Department | M1: Hours | N1: Capacity

Sheet LSV Line 1
A1: Crop | B1: Material Description | C1: Prod. Order | D1: Output Qty | E1: UOM | F1: Scheduled Finish Date (SAP) | G1: Notes: | H1: Priority | I1: PO Status | J1: WorkCenter | K1: Pack Line | L1: Department
A2: PECO | B2: PECO IDALGO PEA RDY ZZZ BK KG | C2: 1002266913 | D2: 164940 | E2: KG | F2: 46286 | G2: PECO PEA RAW RDY Ln2 INT | H2: 5 | I2: NEW | J2: LSVLN1 | K2: LSV Line 1 | L2: LSV Conditioning
A3: PECO | B3: PECO IDALGO PEA RDY ZZZ BK KG | C3: 1002267630 | D3: 56170 | E3: KG | F3: 46286 | G3: PECO PEA RAW RDY Ln2 INT | H3: 2 | I3: NEW | J3: LSVLN1 | K3: LSV Line 1 | L3: LSV Conditioning
A4: SWCO | B4: SWCO GSS3951 CRS CLX ZZZ BK KG | C4: 1002174855 | D4: 48400 | E4: KG | F4: 46021 | G4: SWCO RAX-CLX SUP INT Ln1 | H4: 1 | I4: NEW | J4: LSVLN1 | K4: LSV Line 1 | L4: LSV Conditioning
A5: SWCO | B5: SWCO GH6055 CRN CLX ZZZ BK KG | C5: 1002181889 | D5: 42000 | E5: KG | F5: 46020 | G5: SWCO RAX-CLX STD INT Ln1 | H5: 7 | I5: NEW | J5: LSVLN1 | K5: LSV Line 1 | L5: LSV Conditioning
A6: PECO | B6: PECO SP704-3-8 SNP RDY ZZZ BK KG | C6: 1002266889 | D6: 36310 | E6: KG | F6: 46265 | G6: PECO PEA RAW RDY Ln2 INT | H6: 7 | I6: NEW | J6: LSVLN1 | K6: LSV Line 1 | L6: LSV Conditioning
A7: PECO | B7: PECO SP704-3-8 SNP RDY ZZZ BK KG | C7: 1002266886 | D7: 35230 | E7: KG | F7: 46265 | G7: PECO PEA RAW RDY Ln2 INT | H7: 7 | I7: NEW | J7: LSVLN1 | K7: LSV Line 1 | L7: LSV Conditioning
A8: SWCO | B8: SWCO P&C EARLY CRN RDY ZZZ BK KG | C8: 1002295415 | D8: 24610 | E8: KG | F8: 46341 | G8: SWCO RAW RDY STD INT Ln1 | H8: 3 | I8: NEW | J8: LSVLN1 | K8: LSV Line 1 | L8: LSV Conditioning
A9: SWCO | B9: SWCO GH4927-C CRN RDY ZZZ BK KG | C9: 1002307552 | D9: 24500 | E9: KG | F9: 46325 | G9: SWCO RAW RDY STD INT Ln1 | H9: 5 | I9: NEW | J9: LSVLN1 | K9: LSV Line 1 | L9: LSV Conditioning
A10: PECO | B10: PECO SP704-3-8 SNP RDY ZZZ BK KG | C10: 1002266351 | D10: 23170 | E10: KG | F10: 46265 | G10: PECO PEA RAW RDY Ln2 INT | H10: 7 | I10: NEW | J10: LSVLN1 | K10: LSV Line 1 | L10: LSV Conditioning
A11: SWCO | B11: SWCO GSS1170-R CRS RDF ZZZ BK KG | C11: 1002150398 | D11: 16400 | E11: KG | F11: 46021 | G11: SWCO RAW RDY SUP INT Ln1 | H11: 1 | I11: NEW | J11: LSVLN1 | K11: LSV Line 1 | L11: LSV Conditioning
A12: PECO | B12: PECO SP704-3-8 SNP RDY ZZZ BK KG | C12: 1002266356 | D12: 14930 | E12: KG | F12: 46274 | G12: PECO PEA RAW RDY Ln2 INT | H12: 7 | I12: NEW | J12: LSVLN1 | K12: LSV Line 1 | L12: LSV Conditioning
A13: SWCO | B13: SWCO EA SUNGLOW CRN RDY ZZZ BK KG | C13: 1002295402 | D13: 14185.5 | E13: KG | F13: 46386 | G13: SWCO RAW RDY STD INT Ln1 | H13: 9 | I13: NEW | J13: LSVLN1 | K13: LSV Line 1 | L13: LSV Conditioning
... A16: SWBS | B16: SWBS R00565H S CRS CLD ZZZ BK KG | C16: 1002302915 | D16: 360.5 | E16: KG | F16: 46341 | G16: SWBS RAW-CLD INT Ln1 | H16: 5 | I16: NEW | J16: LSVLN1 | K16: LSV Line 1 | L16: LSV Conditioning

Sheet LSV Line 2
A1: Crop | B1: Material Description | C1: Prod. Order | D1: Output Qty | E1: UOM | F1: Scheduled Finish Date (SAP) | G1: Notes: | H1: Priority | I1: PO Status | J1: WorkCenter | K1: Pack Line | L1: Department
A2: BECO | B2: BECO PISMO RDY ZZZ BK KG | C2: 1002300820 | D2: 125880 | E2: KG | F2: 46384 | G2: BECO RAW RDY Ln2 INT | H2: 6 | I2: NEW | J2: LSVLN2 | K2: LSV Line 2 | L2: LSV Conditioning
A3: BECO | B3: BECO HUNTINGTON RDY ZZZ BK KG | C3: 1002303189 | D3: 99230 | E3: KG | F3: 46384 | G3: BECO RAW RDY Ln2 INT | H3: 5 | I3: NEW | J3: LSVLN2 | K3: LSV Line 2 | L3: LSV Conditioning
A4: BECO | B4: BECO HUNTINGTON RDY ZZZ BK KG | C4: 1002300812 | D4: 89410 | E4: KG | F4: 46384 | G4: BECO RAW RDY Ln2 INT | H4: 5 | I4: NEW | J4: LSVLN2 | K4: LSV Line 2 | L4: LSV Conditioning
A5: BECO | B5: BECO HUNTINGTON RDY ZZZ BK KG | C5: 1002300810 | D5: 69250 | E5: KG | F5: 46384 | G5: BECO RAW RDY Ln2 INT | H5: 5 | I5: NEW | J5: LSVLN2 | K5: LSV Line 2 | L5: LSV Conditioning
A6: BECO | B6: BECO HUNTINGTON RDY ZZZ BK KG | C6: 1002304965 | D6: 65160 | E6: KG | F6: 46384 | G6: BECO RAW RDY Ln2 INT | H6: 5 | I6: NEW | J6: LSVLN2 | K6: LSV Line 2 | L6: LSV Conditioning
A7: BECO | B7: BECO PISMO RDY ZZZ BK KG | C7: 1002300819 | D7: 61900 | E7: KG | F7: 46384 | G7: BECO RAW RDY Ln2 INT | H7: 6 | I7: NEW | J7: LSVLN2 | K7: LSV Line 2 | L7: LSV Conditioning
A8: BECO | B8: BECO HUNTINGTON RDY ZZZ BK KG | C8: 1002300814 | D8: 55510 | E8: KG | F8: 46384 | G8: BECO RAW RDY Ln2 INT | H8: 5 | I8: NEW | J8: LSVLN2 | K8: LSV Line 2 | L8: LSV Conditioning
A9: BECO | B9: BECO PISMO RDY ZZZ BK KG | C9: 1002300822 | D9: 50200 | E9: KG | F9: 46384 | G9: BECO RAW RDY Ln2 INT | H9: 6 | I9: NEW | J9: LSVLN2 | K9: LSV Line 2 | L9: LSV Conditioning
A10: BECO | B10: BECO THOMPSON RDY ZZZ BK KG | C10: 1002300826 | D10: 34140 | E10: KG | F10: 46384 | G10: BECO RAW RDY Ln2 INT | H10: 4 | I10: NEW | J10: LSVLN2 | K10: LSV Line 2 | L10: LSV Conditioning
A11: BECO | B11: BECO SB4876 RDY ZZZ BK KG | C11: 1002300825 | D11: 30760 | E11: KG | F11: 46384 | G11: BECO RAW RDY Ln2 INT | H11: 5 | I11: NEW | J11: LSVLN2 | K11: LSV Line 2 | L11: LSV Conditioning
A12: BEBS | B12: BEBS HUNTINGTON T RDY ZZZ BK KG | C12: 1002303211 | D12: 28890 | E12: KG | F12: 46384 | G12: BEBS RAW RDY Ln2 INT | H12: 5 | I12: NEW | J12: LSVLN2 | K12: LSV Line 2 | L12: LSV Conditioning
A13: BECO | B13: BECO HUNTINGTON RDY ZZZ BK KG | C13: 1002300816 | D13: 24740 | E13: KG | F13: 46384 | G13: BECO RAW RDY Ln2 INT | H13: 5 | I13: NEW | J13: LSVLN2 | K13: LSV Line 2 | L13: LSV Conditioning
... A25: BECO | B25: BECO AUBERON RDY ZZZ BK KG | C25: 1002307905 | D25: 10490 | E25: KG | F25: 46384 | G25: BECO RAW RDY Ln2 INT EAME | H25: 2 | I25: NEW | J25: LSVLN2 | K25: LSV Line 2 | L25: LSV Conditioning
A26: SWTO | B26: SWTO TOLLING SWEETCORN BY RDY ZZZ BK KG | C26: 120000902 | D26: 7173 | E26: KG | F26: 46357 | G26: SWTO RAW RDY Ln2 INT | I26: NEW | J26: LSVLN2 | K26: LSV Line 2 | L26: LSV Conditioning
A27: SWTO | B27: SWTO TOLLING SWEETCORN BY RDY ZZZ BK KG | C27: 120000903 | D27: 6755 | E27: KG | F27: 46357 | G27: SWTO RAW RDY Ln2 INT | I27: NEW | J27: LSVLN2 | K27: LSV Line 2 | L27: LSV Conditioning
A28: SWCO | B28: SWCO OVERLAND CRS CLX ZZZ BK KG | C28: 1002307551 | D28: 6400 | E28: KG | F28: 46324 | G28: SWCO RAX-CLX SUP INT Ln1 | H28: 2 | I28: NEW | J28: LSVLN2 | K28: LSV Line 2 | L28: LSV Conditioning
A29: SWCO | B29: SWCO 3552R CRS RDF ZZZ BK KG | C29: 1002303120 | D29: 5048.5 | E29: KG | F29: 46371 | G29: SWCO RAW RDY INT L2A | H29: 7 | I29: NEW | J29: LSVLN2 | K29: LSV Line 2 | L29: LSV Conditioning
A30: SWTO | B30: SWTO TOLLING SWEETCORN BY RDY ZZZ BK KG | C30: 120000904 | D30: 3987.5 | E30: KG | F30: 46357 | G30: SWTO RAW RDY Ln2 INT | I30: NEW | J30: LSVLN2 | K30: LSV Line 2 | L30: LSV Conditioning
A31: BEBS | B31: BEBS R302089 S RDY ZZZ BK KG | C31: 1002163895 | D31: 3495 | E31: KG | F31: 45986 | G31: BEBS RAW RDY Ln2 INT | H31: 3 | I31: NEW | J31: LSVLN2 | K31: LSV Line 2 | L31: LSV Conditioning
A32: SWCO | B32: SWCO QUICK TRIP CRT RDY ZZZ BK KG | C32: 1002295419 | D32: 3473 | E32: KG | F32: 46386 | G32: SWCO RAW RDY INT L2A | H32: 9 | I32: NEW | J32: LSVLN2 | K32: LSV Line 2 | L32: LSV Conditioning
A33: BECO | B33: BECO KAMARON RDY ZZZ BK KG | C33: 1002303190 | D33: 3460 | E33: KG | F33: 46384 | G33: BECO RAW RDY Ln2 INT EAME | H33: 3 | I33: NEW | J33: LSVLN2 | K33: LSV Line 2 | L33: LSV Conditioning
A34: SWCO | B34: SWCO OVERLAND CRS RDY ZZZ BK KG | C34: 1002307550 | D34: 3300 | E34: KG | F34: 46324 | G34: SWCO RAW RDY SUP INT Ln1 | H34: 4 | I34: NEW | J34: LSVLN2 | K34: LSV Line 2 | L34: LSV Conditioning
A35: BEBS | B35: BEBS HUNTINGTON T RDY ZZZ BK KG | C35: 1002308866 | D35: 2560 | E35: KG | F35: 46384 | G35: BEBS RAW RDY Ln2 INT | H35: 5 | I35: NEW | J35: LSVLN2 | K35: LSV Line 2 | L35: LSV Conditioning
A36: SWBS | B36: SWBS R29153 T CRS CLX ZZZ BK KG | C36: 1002270166 | D36: 1939 | E36: KG | F36: 46164 | G36: SWBS RAX-CLX INT L2B | I36: NEW | J36: LSVLN2 | K36: LSV Line 2 | L36: LSV Conditioning
A37: BEBS | B37: BEBS SB4840 T RDY ZZZ BK KG | C37: 1002303238 | D37: 1720 | E37: KG | F37: 46384 | G37: BEBS RAW RDY Ln2 INT | H37: 1 | I37: NEW | J37: LSVLN2 | K37: LSV Line 2 | L37: LSV Conditioning
A38: BEBS | B38: BEBS HUNTINGTON S RDY ZZZ BK KG | C38: 1002303218 | D38: 1120 | E38: KG | F38: 46384 | G38: BEBS RAW RDY Ln2 INT | H38: 5 | I38: NEW | J38: LSVLN2 | K38: LSV Line 2 | L38: LSV Conditioning
A39: BEBS | B39: BEBS SB4840 S RDY ZZZ BK KG | C39: 1002303237 | D39: 1110 | E39: KG | F39: 46384 | G39: BEBS RAW RDY Ln2 INT | H39: 9 | I39: NEW | J39: LSVLN2 | K39: LSV Line 2 | L39: LSV Conditioning
A40: SWCO | B40: SWCO GSS3378 CRS RDF ZZZ BK KG | C40: 1002282491 | D40: 462.5 | E40: KG | F40: 46219 | G40: SWCO RAW RDY SUP INT L2B | I40: NEW | J40: LSVLN2 | K40: LSV Line 2 | L40: LSV Conditioning
A41: SWCO | B41: SWCO PATRON CRS RDY ZZZ BK KG | C41: 1002309463 | D41: 216.5 | E41: KG | F41: 46387 | G41: SWCO RAW RDY SUP INT L2B | H41: 9 | I41: NEW | J41: LSVLN2 | K41: LSV Line 2 | L41: LSV Conditioning

Sheet LSV Gravity
B1: Crop | C1: Material Description | D1: Prod. Order | E1: Output Qty | F1: UOM | G1: Scheduled Finish Date (SAP) | H1: Notes: | I1: Priority | J1: PO Status | K1: WorkCenter | L1: Pack Line | M1: Department | N1: Hours | O1: Capacity
B2: PECO | C2: PECO KUDO PEA RDY ZZZ BK KG | D2: 2400008091 | E2: 12159 | F2: KG | G2: 46288 | H2: PECO RDY RDY PPur INT | J2: NEW | K2: LSVGRVTY | L2: LSV Gravity | M2: LSV Conditioning
B3: SWBS | C3: SWBS R660D T CRS RDX ZZZ BK KG | D3: 2400008095 | E3: 6047 | F3: KG | G3: 46293 | H3: Gravity 10% high cut | J3: NEW | K3: LSVGRVTY | L3: LSV Gravity | M3: LSV Conditioning
